Workbook

Sheet 입력
A1: ### 1. 계약정보 입력란
A2: 항목 | B2: 값
A3: 가입나이 | B3: 30
A4: 성별 | B4: 남
A5: 보험기간(n) | B5: 100
A6: 납입기간(m) | B6: 20
A7: 가입금액 | B7: 10000000
A8: 상품유형 | B8: 해약환급금 미지급형
A10: ### 2. 기초율 Key-Value 테이블
A11: 구분 | B11: 항목 | C11: 키(Key) | D11: 값1 | E11: 값2 | F11: 비고
A12: 공통기초율 | B12: 예정이율 | C12: interest_rate | D12: 0.0225
A13: 예정사업비율 | B13: α1 (어린이형) | C13: alpha1_child | D13: 0.0004 | F13: 가입금액 대비
A14: 예정사업비율 | B14: α2 (태아형) | C14: alpha2_fetal | D14: 0.039 | E14: n | F14: n: 보험기간
A15: 예정사업비율 | B15: α2 (어린이형) | C15: alpha2_child | D15: 0.05 | E15: Min(n, 20) | F15: n: 보험기간
A16: 예정사업비율 | B16: β1 (태아형) | C16: beta1_fetal | D16: 1e-05 | F16: 가입금액 대비
A17: 예정사업비율 | B17: β1 (어린이형) | C17: beta1_child | D17: 0.0002 | F17: 가입금액 대비
A18: 예정사업비율 | B18: β2 (태아형) | C18: beta2_fetal | D18: 0.1 | F18: 영업보험료 대비
A19: 예정사업비율 | B19: β2 (어린이형) | C19: beta2_child | D19: 0.27 | F19: 영업보험료 대비
A20: 예정사업비율 | B20: β5 (공통) | C20: beta5_common | D20: 0.025 | F20: 영업보험료 대비

Sheet 위험률
A1: 재해장해율 | E1: 보험료 납입면제 관련 위험률 (재해/질병 50% 이상 장해) | K1: 태아보장계수 | N1: ### 3. 예정해지율 테이블
A2: 연령(x) | B2: 남자 위험률(qx) | C2: 여자 위험률(qx) | E2: 연령(x) | F2: 남자 재해 50%이상(qx) | G2: 여자 재해 50%이상(qx) | H2: 남자 질병 50%이상(qx) | I2: 여자 질병 50%이상(qx) | K2: 항목 | L2: 값 | N2: 구분 | O2: 경과기간(t) | P2: 해지율
A3: 0 | B3: 0.00105 | C3: 0.00095 | E3: 0 | F3: 3.8e-05 | G3: 3e-05 | H3: 0.0001 | I3: 8e-05 | K3: 태아보장계수 | L3: 0.475 | N3: 납입중 | O3: 0 | P3: 0.0925
A4: 1 | B4: 0.00045 | C4: 0.0004 | E4: 1 | F4: 2.5e-05 | G4: 2e-05 | H4: 5e-05 | I4: 4e-05 | N4: 납입중 | O4: 1 | P4: 0.1355
A5: 2 | B5: 0.00035 | C5: 0.0003 | E5: 2 | F5: 2e-05 | G5: 1.5e-05 | H5: 3e-05 | I5: 2.5e-05 | N5: 납입중 | O5: 2 | P5: 0.0735
A6: 3 | B6: 0.0003 | C6: 0.00025 | E6: 3 | F6: 1.8e-05 | G6: 1.3e-05 | H6: 2e-05 | I6: 1.8e-05 | N6: 납입중 | O6: 3 | P6: 0.0555
A7: 4 | B7: 0.00025 | C7: 0.0002 | E7: 4 | F7: 1.5e-05 | G7: 1.2e-05 | H7: 1.5e-05 | I7: 1.5e-05 | N7: 납입중 | O7: 4 | P7: 0.06
A8: 5 | B8: 0.00025 | C8: 0.0002 | E8: 5 | F8: 1.5e-05 | G8: 1.2e-05 | H8: 1.5e-05 | I8: 1.5e-05 | N8: 납입중 | O8: 5 | P8: 0.0325
A9: 6 | B9: 0.00025 | C9: 0.0002 | E9: 6 | F9: 1.5e-05 | G9: 1.2e-05 | H9: 1.5e-05 | I9: 1.5e-05 | N9: 납입중 | O9: 6 | P9: 0.0295
A10: 7 | B10: 0.0002 | C10: 0.00015 | E10: 7 | F10: 1.4e-05 | G10: 1.1e-05 | H10: 1.5e-05 | I10: 1.5e-05 | N10: 납입중 | O10: 7 | P10: 0.026
A11: 8 | B11: 0.0002 | C11: 0.00015 | E11: 8 | F11: 1.4e-05 | G11: 1.1e-05 | H11: 1.6e-05 | I11: 1.6e-05 | N11: 납입중 | O11: 8 | P11: 0.023
A12: 9 | B12: 0.0002 | C12: 0.00015 | E12: 9 | F12: 1.4e-05 | G12: 1.1e-05 | H12: 1.7e-05 | I12: 1.7e-05 | N12: 납입중 | O12: 9 | P12: 0.0195
A13: 10 | B13: 0.0002 | C13: 0.00015 | E13: 10 | F13: 1.4e-05 | G13: 1.1e-05 | H13: 1.8e-05 | I13: 1.8e-05 | N13: 납입중 | O13: 10 | P13: 0.016
A14: 11 | B14: 0.0002 | C14: 0.00015 | E14: 11 | F14: 1.4e-05 | G14: 1.1e-05 | H14: 2e-05 | I14: 2e-05 | N14: 납입중 | O14: 11 | P14: 0.0135
A15: 12 | B15: 0.0002 | C15: 0.00015 | E15: 12 | F15: 1.4e-05 | G15: 1.1e-05 | H15: 2.2e-05 | I15: 2.2e-05 | N15: 납입후 | O15: m≤t<m+1 | P15: 0.215
A16: 13 | B16: 0.00025 | C16: 0.00015 | E16: 13 | F16: 1.8e-05 | G16: 1.2e-05 | H16: 2.5e-05 | I16: 2.5e-05 | N16: 납입후 | O16: m+1≤t<m+2 | P16: 0.032
A17: 14 | B17: 0.0003 | C17: 0.0002 | E17: 14 | F17: 2.2e-05 | G17: 1.4e-05 | H17: 2.8e-05 | I17: 2.8e-05 | N17: 납입후 | O17: m+2≤t<m+5 | P17: 0.01
A18: 15 | B18: 0.00035 | C18: 0.0002 | E18: 15 | F18: 2.6e-05 | G18: 1.5e-05 | H18: 3.2e-05 | I18: 3.2e-05 | N18: 납입후 | O18: m+5≤t<m+6 | P18: 0.008
A19: 16 | B19: 0.0004 | C19: 0.0002 | E19: 16 | F19: 3e-05 | G19: 1.6e-05 | H19: 3.8e-05 | I19: 3.8e-05 | N19: 납입후 | O19: t≥m+6 | P19: 0.01
A20: 17 | B20: 0.00045 | C20: 0.00025 | E20: 17 | F20: 3.4e-05 | G20: 1.8e-05 | H20: 4.5e-05 | I20: 4.5e-05
A21: 18 | B21: 0.00045 | C21: 0.00025 | E21: 18 | F21: 3.4e-05 | G21: 1.8e-05 | H21: 5.2e-05 | I21: 5.2e-05
A22: 19 | B22: 0.00045 | C22: 0.00025 | E22: 19 | F22: 3.4e-05 | G22: 1.8e-05 | H22: 6e-05 | I22: 6e-05
A23: 20 | B23: 0.00045 | C23: 0.00025 | E23: 20 | F23: 3.4e-05 | G23: 1.8e-05 | H23: 6.8e-05 | I23: 6.8e-05
A24: 21 | B24: 0.0005 | C24: 0.00025 | E24: 21 | F24: 3.8e-05 | G24: 1.9e-05 | H24: 7.8e-05 | I24: 7.8e-05
A25: 22 | B25: 0.0005 | C25: 0.00025 | E25: 22 | F25: 3.8e-05 | G25: 1.9e-05 | H25: 8.8e-05 | I25: 8.8e-05
A26: 23 | B26: 0.0005 | C26: 0.00025 | E26: 23 | F26: 3.8e-05 | G26: 1.9e-05 | H26: 0.0001 | I26: 0.0001
A27: 24 | B27: 0.0005 | C27: 0.00025 | E27: 24 | F27: 3.8e-05 | G27: 1.9e-05 | H27: 0.000112 | I27: 0.000112
A28: 25 | B28: 0.00055 | C28: 0.0003 | E28: 25 | F28: 4.2e-05 | G28: 2.1e-05 | H28: 0.000125 | I28: 0.000125
A29: 26 | B29: 0.00055 | C29: 0.0003 | E29: 26 | F29: 4.2e-05 | G29: 2.1e-05 | H29: 0.000138 | I29: 0.000138
A30: 27 | B30: 0.00055 | C30: 0.0003 | E30: 27 | F30: 4.2e-05 | G30: 2.1e-05 | H30: 0.000152 | I30: 0.000152
A31: 28 | B31: 0.00055 | C31: 0.0003 | E31: 28 | F31: 4.2e-05 | G31: 2.1e-05 | H31: 0.000168 | I31: 0.000168
... A53: 50 | B53: 0.001 | C53: 0.00055 | E53: 50 | F53: 7.8e-05 | G53: 3.7e-05 | H53: 0.001115 | I53: 0.001115

Sheet 계산
B1: A | C1: B | D1: C | E1: D | F1: E | G1: F
A2: 1 | B2: 경과년도(t) | C2: 연령(x+t) | D2: 사망률(qx) | E2: 장해율(장해qx) | F2: 납면율(납면qx) | G2: 해지율(w)
A3: 2 | B3: 0 | C3: =입력!$B$1 -> 0 | D3: =VLOOKUP(B2, 입력!$B$11:$D$121, IF(입력!$B$2="남",2,3), FALSE) -> #N/A | E3: (재해장해율 조회) | F3: (재해+질병 납면율 조회) | G3: =VLOOKUP(A2, 입력!$F$29:$G$41, 2, TRUE) -> #N/A
A4: 3 | B4: =A2+1 -> 2 | C4: =B2+1 -> #VALUE! | D4: =VLOOKUP(B3, 입력!$B$11:$D$121, IF(입력!$B$2="남",2,3), FALSE) -> #N/A | E4: (재해장해율 조회) | F4: (재해+질병 납면율 조회) | G4: =IF(A3>=입력!$B$5, VLOOKUP("m≤t<m+1", 입력!$F$44:$G$48, 2, FALSE), VLOOKUP(A3, 입력!$F$29:$G$41, 2, TRUE)) -> #N/A

Sheet 기수표
A1: 연령(x) | B1: 생존자수(lx) | C1: 사망률(qx) | D1: 사망자수(dx) | E1: Dx | F1: Nx | G1: Cx | H1: Mx
A2: 30 | B2: 100000 | C2: =VLOOKUP(A2, 위험률_확장!$A$3:$C$123, IF(입력!$B$4="남", 2, 3), FALSE) -> 0.0006 | D2: =B2*C2 -> 60 | E2: =B2*(1/(1+0.0225))^A2 -> 51298.008 | F2: =SUM(E2:E$92) -> 1969997.5 | G2: =D2*(1/(1+0.0225))^(A2+1) -> 30.10152 | H2: =SUM(G2:G$92) -> 1738.7782
A3: 31 | B3: =B2-D2 -> 99940 | C3: =VLOOKUP(A3, 위험률_확장!$A$3:$C$123, IF(입력!$B$4="남", 2, 3), FALSE) -> 0.0006 | D3: =B3*C3 -> 59.964 | E3: =B3*(1/(1+0.0225))^A3 -> 50139.099 | F3: =SUM(E3:E$92) -> 1918699.5 | G3: =D3*(1/(1+0.0225))^(A3+1) -> 29.421476 | H3: =SUM(G3:G$92) -> 1708.6767
A4: 32 | B4: =B3-D3 -> 99880.036 | C4: =VLOOKUP(A4, 위험률_확장!$A$3:$C$123, IF(입력!$B$4="남", 2, 3), FALSE) -> 0.00065 | D4: =B4*C4 -> 64.922023 | E4: =B4*(1/(1+0.0225))^A4 -> 49006.372 | F4: =SUM(E4:E$92) -> 1868560.4 | G4: =D4*(1/(1+0.0225))^(A4+1) -> 31.153195 | H4: =SUM(G4:G$92) -> 1679.2552
A5: 33 | B5: =B4-D4 -> 99815.114 | C5: =VLOOKUP(A5, 위험률_확장!$A$3:$C$123, IF(입력!$B$4="남", 2, 3), FALSE) -> 0.00065 | D5: =B5*C5 -> 64.879824 | E5: =B5*(1/(1+0.0225))^A5 -> 47896.839 | F5: =SUM(E5:E$92) -> 1819554 | G5: =D5*(1/(1+0.0225))^(A5+1) -> 30.447869 | H5: =SUM(G5:G$92) -> 1648.102
A6: 34 | B6: =B5-D5 -> 99750.234 | C6: =VLOOKUP(A6, 위험률_확장!$A$3:$C$123, IF(입력!$B$4="남", 2, 3), FALSE) -> 0.0007 | D6: =B6*C6 -> 69.825164 | E6: =B6*(1/(1+0.0225))^A6 -> 46812.427 | F6: =SUM(E6:E$92) -> 1771657.2 | G6: =D6*(1/(1+0.0225))^(A6+1) -> 32.047627 | H6: =SUM(G6:G$92) -> 1617.6541
A7: 35 | B7: =B6-D6 -> 99680.409 | C7: =VLOOKUP(A7, 위험률_확장!$A$3:$C$123, IF(입력!$B$4="남", 2, 3), FALSE) -> 0.0007 | D7: =B7*C7 -> 69.776286 | E7: =B7*(1/(1+0.0225))^A7 -> 45750.277 | F7: =SUM(E7:E$92) -> 1724844.8 | G7: =D7*(1/(1+0.0225))^(A7+1) -> 31.320483 | H7: =SUM(G7:G$92) -> 1585.6065
A8: 36 | B8: =B7-D7 -> 99610.633 | C8: =VLOOKUP(A8, 위험률_확장!$A$3:$C$123, IF(입력!$B$4="남", 2, 3), FALSE) -> 0.0007 | D8: =B8*C8 -> 69.727443 | E8: =B8*(1/(1+0.0225))^A8 -> 44712.227 | F8: =SUM(E8:E$92) -> 1679094.5 | G8: =D8*(1/(1+0.0225))^(A8+1) -> 30.609837 | H8: =SUM(G8:G$92) -> 1554.286
A9: 37 | B9: =B8-D8 -> 99540.905 | C9: =VLOOKUP(A9, 위험률_확장!$A$3:$C$123, IF(입력!$B$4="남", 2, 3), FALSE) -> 0.00075 | D9: =B9*C9 -> 74.655679 | E9: =B9*(1/(1+0.0225))^A9 -> 43697.729 | F9: =SUM(E9:E$92) -> 1634382.3 | G9: =D9*(1/(1+0.0225))^(A9+1) -> 32.052124 | H9: =SUM(G9:G$92) -> 1523.6762
A10: 38 | B10: =B9-D9 -> 99466.25 | C10: =VLOOKUP(A10, 위험률_확장!$A$3:$C$123, IF(입력!$B$4="남", 2, 3), FALSE) -> 0.00075 | D10: =B10*C10 -> 74.599687 | E10: =B10*(1/(1+0.0225))^A10 -> 42704.113 | F10: =SUM(E10:E$92) -> 1590684.5 | G10: =D10*(1/(1+0.0225))^(A10+1) -> 31.323311 | H10: =SUM(G10:G$92) -> 1491.6241
A11: 39 | B11: =B10-D10 -> 99391.65 | C11: =VLOOKUP(A11, 위험률_확장!$A$3:$C$123, IF(입력!$B$4="남", 2, 3), FALSE) -> 0.00075 | D11: =B11*C11 -> 74.543737 | E11: =B11*(1/(1+0.0225))^A11 -> 41733.091 | F11: =SUM(E11:E$92) -> 1547980.4 | G11: =D11*(1/(1+0.0225))^(A11+1) -> 30.611069 | H11: =SUM(G11:G$92) -> 1460.3007
A12: 40 | B12: =B11-D11 -> 99317.106 | C12: =VLOOKUP(A12, 위험률_확장!$A$3:$C$123, IF(입력!$B$4="남", 2, 3), FALSE) -> 0.00075 | D12: =B12*C12 -> 74.48783 | E12: =B12*(1/(1+0.0225))^A12 -> 40784.148 | F12: =SUM(E12:E$92) -> 1506247.3 | G12: =D12*(1/(1+0.0225))^(A12+1) -> 29.915023 | H12: =SUM(G12:G$92) -> 1429.6897
A13: 41 | B13: =B12-D12 -> 99242.618 | C13: =VLOOKUP(A13, 위험률_확장!$A$3:$C$123, IF(입력!$B$4="남", 2, 3), FALSE) -> 0.0008 | D13: =B13*C13 -> 79.394095 | E13: =B13*(1/(1+0.0225))^A13 -> 39856.782 | F13: =SUM(E13:E$92) -> 1465463.2 | G13: =D13*(1/(1+0.0225))^(A13+1) -> 31.18379 | H13: =SUM(G13:G$92) -> 1399.7747
A14: 42 | B14: =B13-D13 -> 99163.224 | C14: =VLOOKUP(A14, 위험률_확장!$A$3:$C$123, IF(입력!$B$4="남", 2, 3), FALSE) -> 0.0008 | D14: =B14*C14 -> 79.330579 | E14: =B14*(1/(1+0.0225))^A14 -> 38948.554 | F14: =SUM(E14:E$92) -> 1425606.4 | G14: =D14*(1/(1+0.0225))^(A14+1) -> 30.473196 | H14: =SUM(G14:G$92) -> 1368.5909
... A92: 120 | B92: =B91-D91 -> 91783.161 | C92: =VLOOKUP(A92, 위험률_확장!$A$3:$C$123, IF(입력!$B$4="남", 2, 3), FALSE) -> 0.001 | D92: =B92*C92 -> 91.783161 | E92: =B92*(1/(1+0.0225))^A92 -> 6355.7237 | F92: =SUM(E92:E$92) -> 6355.7237 | G92: =D92*(1/(1+0.0225))^(A92+1) -> 6.2158667 | H92: =SUM(G92:G$92) -> 6.2158667

Sheet 위험률_확장
A1: 재해장해율 | E1: 보험료 납입면제 관련 위험률 (재해/질병 50% 이상 장해) | K1: 태아보장계수 | N1: ### 3. 예정해지율 테이블
A2: 연령(x) | B2: 남자 위험률(qx) | C2: 여자 위험률(qx) | E2: 연령(x) | F2: 남자 재해 50%이상(qx) | G2: 여자 재해 50%이상(qx) | H2: 남자 질병 50%이상(qx) | I2: 여자 질병 50%이상(qx) | K2: 항목 | L2: 값 | N2: 구분 | O2: 경과기간(t) | P2: 해지율
A3: 0 | B3: 0.00105 | C3: 0.00095 | E3: 0 | F3: 3.8e-05 | G3: 3e-05 | H3: 0.0001 | I3: 8e-05 | K3: 태아보장계수 | L3: 0.475 | N3: 납입중 | O3: 0 | P3: 0.0925
A4: 1 | B4: 0.00045 | C4: 0.0004 | E4: 1 | F4: 2.5e-05 | G4: 2e-05 | H4: 5e-05 | I4: 4e-05 | N4: 납입중 | O4: 1 | P4: 0.1355
A5: 2 | B5: 0.00035 | C5: 0.0003 | E5: 2 | F5: 2e-05 | G5: 1.5e-05 | H5: 3e-05 | I5: 2.5e-05 | N5: 납입중 | O5: 2 | P5: 0.0735
A6: 3 | B6: 0.0003 | C6: 0.00025 | E6: 3 | F6: 1.8e-05 | G6: 1.3e-05 | H6: 2e-05 | I6: 1.8e-05 | N6: 납입중 | O6: 3 | P6: 0.0555
A7: 4 | B7: 0.00025 | C7: 0.0002 | E7: 4 | F7: 1.5e-05 | G7: 1.2e-05 | H7: 1.5e-05 | I7: 1.5e-05 | N7: 납입중 | O7: 4 | P7: 0.06
A8: 5 | B8: 0.00025 | C8: 0.0002 | E8: 5 | F8: 1.5e-05 | G8: 1.2e-05 | H8: 1.5e-05 | I8: 1.5e-05 | N8: 납입중 | O8: 5 | P8: 0.0325
A9: 6 | B9: 0.00025 | C9: 0.0002 | E9: 6 | F9: 1.5e-05 | G9: 1.2e-05 | H9: 1.5e-05 | I9: 1.5e-05 | N9: 납입중 | O9: 6 | P9: 0.0295
A10: 7 | B10: 0.0002 | C10: 0.00015 | E10: 7 | F10: 1.4e-05 | G10: 1.1e-05 | H10: 1.5e-05 | I10: 1.5e-05 | N10: 납입중 | O10: 7 | P10: 0.026
A11: 8 | B11: 0.0002 | C11: 0.00015 | E11: 8 | F11: 1.4e-05 | G11: 1.1e-05 | H11: 1.6e-05 | I11: 1.6e-05 | N11: 납입중 | O11: 8 | P11: 0.023
A12: 9 | B12: 0.0002 | C12: 0.00015 | E12: 9 | F12: 1.4e-05 | G12: 1.1e-05 | H12: 1.7e-05 | I12: 1.7e-05 | N12: 납입중 | O12: 9 | P12: 0.0195
A13: 10 | B13: 0.0002 | C13: 0.00015 | E13: 10 | F13: 1.4e-05 | G13: 1.1e-05 | H13: 1.8e-05 | I13: 1.8e-05 | N13: 납입중 | O13: 10 | P13: 0.016
A14: 11 | B14: 0.0002 | C14: 0.00015 | E14: 11 | F14: 1.4e-05 | G14: 1.1e-05 | H14: 2e-05 | I14: 2e-05 | N14: 납입중 | O14: 11 | P14: 0.0135
A15: 12 | B15: 0.0002 | C15: 0.00015 | E15: 12 | F15: 1.4e-05 | G15: 1.1e-05 | H15: 2.2e-05 | I15: 2.2e-05 | N15: 납입후 | O15: m≤t<m+1 | P15: 0.215
A16: 13 | B16: 0.00025 | C16: 0.00015 | E16: 13 | F16: 1.8e-05 | G16: 1.2e-05 | H16: 2.5e-05 | I16: 2.5e-05 | N16: 납입후 | O16: m+1≤t<m+2 | P16: 0.032
A17: 14 | B17: 0.0003 | C17: 0.0002 | E17: 14 | F17: 2.2e-05 | G17: 1.4e-05 | H17: 2.8e-05 | I17: 2.8e-05 | N17: 납입후 | O17: m+2≤t<m+5 | P17: 0.01
A18: 15 | B18: 0.00035 | C18: 0.0002 | E18: 15 | F18: 2.6e-05 | G18: 1.5e-05 | H18: 3.2e-05 | I18: 3.2e-05 | N18: 납입후 | O18: m+5≤t<m+6 | P18: 0.008
A19: 16 | B19: 0.0004 | C19: 0.0002 | E19: 16 | F19: 3e-05 | G19: 1.6e-05 | H19: 3.8e-05 | I19: 3.8e-05 | N19: 납입후 | O19: t≥m+6 | P19: 0.01
A20: 17 | B20: 0.00045 | C20: 0.00025 | E20: 17 | F20: 3.4e-05 | G20: 1.8e-05 | H20: 4.5e-05 | I20: 4.5e-05
A21: 18 | B21: 0.00045 | C21: 0.00025 | E21: 18 | F21: 3.4e-05 | G21: 1.8e-05 | H21: 5.2e-05 | I21: 5.2e-05
A22: 19 | B22: 0.00045 | C22: 0.00025 | E22: 19 | F22: 3.4e-05 | G22: 1.8e-05 | H22: 6e-05 | I22: 6e-05
A23: 20 | B23: 0.00045 | C23: 0.00025 | E23: 20 | F23: 3.4e-05 | G23: 1.8e-05 | H23: 6.8e-05 | I23: 6.8e-05
A24: 21 | B24: 0.0005 | C24: 0.00025 | E24: 21 | F24: 3.8e-05 | G24: 1.9e-05 | H24: 7.8e-05 | I24: 7.8e-05
A25: 22 | B25: 0.0005 | C25: 0.00025 | E25: 22 | F25: 3.8e-05 | G25: 1.9e-05 | H25: 8.8e-05 | I25: 8.8e-05
A26: 23 | B26: 0.0005 | C26: 0.00025 | E26: 23 | F26: 3.8e-05 | G26: 1.9e-05 | H26: 0.0001 | I26: 0.0001
A27: 24 | B27: 0.0005 | C27: 0.00025 | E27: 24 | F27: 3.8e-05 | G27: 1.9e-05 | H27: 0.000112 | I27: 0.000112
A28: 25 | B28: 0.00055 | C28: 0.0003 | E28: 25 | F28: 4.2e-05 | G28: 2.1e-05 | H28: 0.000125 | I28: 0.000125
A29: 26 | B29: 0.00055 | C29: 0.0003 | E29: 26 | F29: 4.2e-05 | G29: 2.1e-05 | H29: 0.000138 | I29: 0.000138
A30: 27 | B30: 0.00055 | C30: 0.0003 | E30: 27 | F30: 4.2e-05 | G30: 2.1e-05 | H30: 0.000152 | I30: 0.000152
A31: 28 | B31: 0.00055 | C31: 0.0003 | E31: 28 | F31: 4.2e-05 | G31: 2.1e-05 | H31: 0.000168 | I31: 0.000168
... A53: 50 | B53: 0.001 | C53: 0.00055 | E53: 50 | F53: 7.8e-05 | G53: 3.7e-05 | H53: 0.001115 | I53: 0.001115
A54: 51 | B54: 0.001 | C54: 0.00055
A55: 52 | B55: 0.001 | C55: 0.00055
A56: 53 | B56: 0.001 | C56: 0.00055
A57: 54 | B57: 0.001 | C57: 0.00055
A58: 55 | B58: 0.001 | C58: 0.00055
A59: 56 | B59: 0.001 | C59: 0.00055
A60: 57 | B60: 0.001 | C60: 0.00055
A61: 58 | B61: 0.001 | C61: 0.00055
...
