Workbook

Sheet 입력
A1: 구분 | B1: 항목 | C1: 입력값 | D1: 비고 / 선택 옵션 | E1: 관련 근거 | F1: 참조 값
A2: 공통 | B2: 가입 유형 | D2: 선택: 어린이형,태아형 | E2: 2.가, 2.나 | F2: =IFERROR(VLOOKUP(C2, data_mapping!A1:B2, 2, FALSE), "")
A3: 공통 | B3: 상품 종류 | D3: 선택: 해약환급금 미지급형,일반형 | E3: 보험종목의 명칭, 2.가 | F3: =IFERROR(VLOOKUP(C3, data_mapping!A3:B4, 2, FALSE), "")
A4: 주계약 | B4: 갱신 여부 | E4: 보험종목의 명칭
A5: 주계약 | B5: 보험 기간 | D5: 선택: 30세만기,100세만기 | E5: 2.가 | F5: =IFERROR(VLOOKUP(C5, data_mapping!A5:B6, 2, FALSE), "")
A6: 주계약 | B6: 납입 기간 | D6: 선택: 5년납,10년납,20년납,30년납,전기납 | E6: 2.가 | F6: =IFERROR(VLOOKUP(C6, data_mapping!A7:B11, 2, FALSE), "")
A7: 일반암진단특약 | B7: 갱신 여부 | E7: 보험종목의 명칭
A8: 일반암진단특약 | B8: 보험 기간 | D8: 선택: 30세만기,100세만기 | E8: 2.가 | F8: =IFERROR(VLOOKUP(C8, data_mapping!A12:B13, 2, FALSE), "")
A9: 일반암진단특약 | B9: 납입 기간 | D9: 선택: 5년납,10년납,20년납,30년납,전기납 | E9: 2.가 | F9: =IFERROR(VLOOKUP(C9, data_mapping!A14:B18, 2, FALSE), "")
A10: 고액암진단특약 | B10: 갱신 여부 | E10: 보험종목의 명칭
A11: 고액암진단특약 | B11: 보험 기간 | D11: 선택: 30세만기,100세만기 | E11: 2.가 | F11: =IFERROR(VLOOKUP(C11, data_mapping!A19:B20, 2, FALSE), "")
A12: 고액암진단특약 | B12: 납입 기간 | D12: 선택: 5년납,10년납,20년납,30년납,전기납 | E12: 2.가 | F12: =IFERROR(VLOOKUP(C12, data_mapping!A21:B25, 2, FALSE), "")
A13: 남녀특정암진단특약 | B13: 갱신 여부 | E13: 보험종목의 명칭
A14: 남녀특정암진단특약 | B14: 보험 기간 | D14: 선택: 30세만기,100세만기 | E14: 2.가 | F14: =IFERROR(VLOOKUP(C14, data_mapping!A26:B27, 2, FALSE), "")
A15: 남녀특정암진단특약 | B15: 납입 기간 | D15: 선택: 5년납,10년납,20년납,30년납,전기납 | E15: 2.가 | F15: =IFERROR(VLOOKUP(C15, data_mapping!A28:B32, 2, FALSE), "")
A16: 소액암진단특약 | B16: 갱신 여부 | E16: 보험종목의 명칭
A17: 소액암진단특약 | B17: 보험 기간 | D17: 선택: 30세만기,100세만기 | E17: 2.가 | F17: =IFERROR(VLOOKUP(C17, data_mapping!A33:B34, 2, FALSE), "")
A18: 소액암진단특약 | B18: 납입 기간 | D18: 선택: 5년납,10년납,20년납,30년납,전기납 | E18: 2.가 | F18: =IFERROR(VLOOKUP(C18, data_mapping!A35:B39, 2, FALSE), "")
A19: 주니어특정중대질병진단특약 | B19: 갱신 여부 | E19: 보험종목의 명칭
A20: 주니어특정중대질병진단특약 | B20: 보험 기간 | D20: 선택: 30세만기,100세만기 | E20: 2.가 | F20: =IFERROR(VLOOKUP(C20, data_mapping!A40:B41, 2, FALSE), "")
A21: 주니어특정중대질병진단특약 | B21: 납입 기간 | D21: 선택: 5년납,10년납,20년납,30년납,전기납 | E21: 2.가 | F21: =IFERROR(VLOOKUP(C21, data_mapping!A42:B46, 2, FALSE), "")
A22: 주니어특정중대질병수술보장특약 | B22: 갱신 여부 | E22: 보험종목의 명칭
A23: 주니어특정중대질병수술보장특약 | B23: 보험 기간 | D23: 선택: 30세만기,100세만기 | E23: 2.가 | F23: =IFERROR(VLOOKUP(C23, data_mapping!A47:B48, 2, FALSE), "")
A24: 주니어특정중대질병수술보장특약 | B24: 납입 기간 | D24: 선택: 5년납,10년납,20년납,30년납,전기납 | E24: 2.가 | F24: =IFERROR(VLOOKUP(C24, data_mapping!A49:B53, 2, FALSE), "")
A25: 뇌출혈진단특약 | B25: 갱신 여부 | E25: 보험종목의 명칭
A26: 뇌출혈진단특약 | B26: 보험 기간 | D26: 선택: 100세만기 | E26: 2.가 | F26: =IFERROR(VLOOKUP(C26, data_mapping!A54:B54, 2, FALSE), "")
A27: 뇌출혈진단특약 | B27: 납입 기간 | D27: 선택: 10년납,20년납,30년납 | E27: 2.가 | F27: =IFERROR(VLOOKUP(C27, data_mapping!A55:B57, 2, FALSE), "")
A28: 급성심근경색증진단특약 | B28: 갱신 여부 | E28: 보험종목의 명칭
A29: 급성심근경색증진단특약 | B29: 보험 기간 | D29: 선택: 100세만기 | E29: 2.가 | F29: =IFERROR(VLOOKUP(C29, data_mapping!A58:B58, 2, FALSE), "")
A30: 급성심근경색증진단특약 | B30: 납입 기간 | D30: 선택: 10년납,20년납,30년납 | E30: 2.가 | F30: =IFERROR(VLOOKUP(C30, data_mapping!A59:B61, 2, FALSE), "")
A31: 뇌혈관질환진단특약 | B31: 갱신 여부 | E31: 보험종목의 명칭
A32: 뇌혈관질환진단특약 | B32: 보험 기간 | D32: 선택: 100세만기 | E32: 2.가 | F32: =IFERROR(VLOOKUP(C32, data_mapping!A62:B62, 2, FALSE), "")
A33: 뇌혈관질환진단특약 | B33: 납입 기간 | D33: 선택: 10년납,20년납,30년납 | E33: 2.가 | F33: =IFERROR(VLOOKUP(C33, data_mapping!A63:B65, 2, FALSE), "")
A34: 허혈심장질환진단특약 | B34: 갱신 여부 | E34: 보험종목의 명칭
A35: 허혈심장질환진단특약 | B35: 보험 기간 | D35: 선택: 100세만기 | E35: 2.가 | F35: =IFERROR(VLOOKUP(C35, data_mapping!A66:B66, 2, FALSE), "")
A36: 허혈심장질환진단특약 | B36: 납입 기간 | D36: 선택: 10년납,20년납,30년납 | E36: 2.가 | F36: =IFERROR(VLOOKUP(C36, data_mapping!A67:B69, 2, FALSE), "")
A37: 질병장해특약 | B37: 갱신 여부 | E37: 보험종목의 명칭
A38: 질병장해특약 | B38: 보험 기간 | D38: 선택: 30세만기,100세만기 | E38: 2.가 | F38: =IFERROR(VLOOKUP(C38, data_mapping!A70:B71, 2, FALSE), "")
A39: 질병장해특약 | B39: 납입 기간 | D39: 선택: 5년납,10년납,20년납,30년납,전기납 | E39: 2.가 | F39: =IFERROR(VLOOKUP(C39, data_mapping!A72:B76, 2, FALSE), "")
A40: 첫날부터플러스입원보장특약 | B40: 갱신 여부 | E40: 보험종목의 명칭
...

Sheet data_mapping
A1: 어린이형 | B1: 어린이형
A2: 태아형 | B2: 태아형
A3: 해약환급금 미지급형 | B3: 해약환급금 미지급형
A4: 일반형 | B4: 일반형
A5: 30세만기 | B5: 30
A6: 100세만기 | B6: 100
A7: 5년납 | B7: 5
A8: 10년납 | B8: 10
A9: 20년납 | B9: 20
A10: 30년납 | B10: 30
A11: 전기납 | B11: 전기납
A12: 30세만기 | B12: 30
A13: 100세만기 | B13: 100
A14: 5년납 | B14: 5
A15: 10년납 | B15: 10
A16: 20년납 | B16: 20
A17: 30년납 | B17: 30
A18: 전기납 | B18: 전기납
A19: 30세만기 | B19: 30
A20: 100세만기 | B20: 100
A21: 5년납 | B21: 5
A22: 10년납 | B22: 10
A23: 20년납 | B23: 20
A24: 30년납 | B24: 30
A25: 전기납 | B25: 전기납
A26: 30세만기 | B26: 30
A27: 100세만기 | B27: 100
A28: 5년납 | B28: 5
A29: 10년납 | B29: 10
A30: 20년납 | B30: 20
A31: 30년납 | B31: 30
A32: 전기납 | B32: 전기납
A33: 30세만기 | B33: 30
A34: 100세만기 | B34: 100
A35: 5년납 | B35: 5
A36: 10년납 | B36: 10
A37: 20년납 | B37: 20
A38: 30년납 | B38: 30
A39: 전기납 | B39: 전기납
A40: 30세만기 | B40: 30
...
